{
    "type": [
        2,
        2,
        0,
        1,
        3,
        0,
        1,
        0,
        1,
        0,
        1,
        0,
        0,
        1,
        0,
        0,
        1,
        0,
        0,
        1,
        3,
        0,
        0,
        1,
        0,
        1,
        0,
        1,
        0,
        1,
        0,
        1,
        0,
        1,
        0,
        1,
        0,
        1,
        0,
        1,
        0,
        1,
        0,
        1,
        0,
        1,
        0,
        1,
        0,
        1,
        0,
        1,
        0,
        1,
        0,
        1,
        0,
        0,
        1,
        0,
        1,
        0,
        1,
        0,
        1,
        0,
        1,
        0,
        1,
        0,
        1,
        0,
        1,
        0,
        1,
        0,
        1,
        0,
        1,
        0,
        1,
        0,
        1,
        0,
        1,
        0,
        1,
        0,
        1,
        0,
        1,
        0,
        1,
        0,
        1,
        0,
        1,
        0,
        1,
        0,
        1,
        0,
        1,
        0,
        1,
        0,
        1,
        0,
        1,
        0,
        1,
        0,
        1,
        0,
        1,
        0,
        0,
        0,
        0,
        0,
        1,
        0,
        1,
        0,
        1,
        0,
        1,
        3,
        2,
        2,
        2,
        2,
        3,
        2,
        3,
        3,
        3,
        3,
        3,
        3,
        3,
        3,
        3,
        3,
        3,
        3,
        3,
        3,
        3,
        3,
        3,
        3,
        3,
        3,
        3,
        3,
        3,
        3,
        3,
        3,
        3,
        3,
        3,
        3,
        3,
        3,
        3,
        3,
        3,
        3,
        3,
        3,
        3,
        3,
        3,
        3,
        2,
        2,
        0,
        1,
        3,
        0,
        1,
        0,
        1,
        0,
        1,
        0,
        0,
        1,
        0,
        1,
        0,
        1,
        0,
        1,
        0,
        1,
        0,
        0,
        1,
        0,
        1,
        0,
        1,
        0,
        1,
        0,
        1,
        0,
        1,
        0,
        1,
        0,
        1,
        0,
        1,
        0,
        1,
        0,
        1,
        0,
        1,
        0,
        1,
        0,
        1,
        0,
        1,
        0,
        1,
        0,
        1,
        0,
        0,
        1,
        0,
        1,
        0,
        1,
        0,
        1,
        0,
        1,
        0,
        1,
        0,
        1,
        0,
        1,
        0,
        1,
        0,
        1,
        0,
        1,
        0,
        1,
        0,
        1,
        0,
        1,
        0,
        1,
        0,
        1,
        0,
        1,
        0,
        1,
        0,
        1,
        0,
        1,
        0,
        1,
        0,
        1,
        0,
        1,
        0,
        1,
        0,
        1,
        0,
        1,
        0,
        1,
        0,
        1,
        0,
        1,
        0,
        1,
        0,
        1,
        0,
        1,
        0,
        1,
        0,
        1,
        0,
        1,
        0,
        1,
        0,
        1,
        0,
        0,
        1,
        3,
        0,
        1,
        0,
        0,
        1,
        0,
        0,
        1,
        0,
        1,
        3,
        0,
        1,
        0,
        1,
        0,
        1,
        2,
        3,
        2
    ],
    "data": [
        "\nR version 4.3.3 (2024-02-29 ucrt) -- \"Angel Food Cake\"\nCopyright (C) 2024 The R Foundation for Statistical Computing\nPlatform: x86_64-w64-mingw32/x64 (64-bit)\n\nR is free software and comes with ABSOLUTELY NO WARRANTY.\nYou are welcome to redistribute it under certain conditions.\nType 'license()' or 'licence()' for distribution details.\n\n  Natural language support but running in an English locale\n\nR is a collaborative project with many contributors.\nType 'contributors()' for more information and\n'citation()'",
        " on how to cite R or R packages in publications.\n\nType 'demo()' for some demos, 'help()' for on-line help, or\n'help.start()' for an HTML browser interface to help.\nType 'q()' to quit R.\n\n- Project '~/QUARTOPROJECT' loaded. [renv 1.0.7]\n- The project is out-of-sync -- use `renv::status()` for details.\n[Workspace loaded from ~/QUARTOPROJECT/.RData]\r\n\r\n",
        "> ",
        "reticulate::repl_python()",
        "Python 3.12.3 (C:/Users/C25Weston.Peene/AppData/Local/Programs/Python/Python312/python.exe)\nReticulate 1.36.0 REPL -- A Python interpreter in R.\nEnter 'exit' or 'quit' to exit the REPL and return to R.\n",
        ">>> ",
        "from shiny import App, render, ui, reactive",
        ">>> ",
        "import requests",
        ">>> ",
        "from flask import Flask",
        ">>> ",
        ">>> ",
        "app = Flask(__name__)",
        ">>> ",
        ">>> ",
        "@app.route('/')",
        "... ",
        "... ",
        "api_url = 'http://127.0.0.1:8080/predict'",
        "  File \"<string>\", line 1\n    @app.route('/')\nSyntaxError: invalid syntax\n",
        ">>> ",
        ">>> ",
        "app_ui = ui.page_fluid(",
        "... ",
        "    ui.panel_title(\"Penguin Mass Predictor\"), ",
        "... ",
        "    ui.layout_sidebar(",
        "... ",
        "        ui.panel_sidebar(",
        "... ",
        "            [ui.input_slider(\"bill_length\", \"Bill Length (mm)\", 30, 60, 45, step = 0.1),",
        "... ",
        "            ui.input_select(\"sex\", \"Sex\", [\"Male\", \"Female\"]),",
        "... ",
        "            ui.input_select(\"species\", \"Species\", [\"Adelie\", \"Chinstrap\", \"Gentoo\"]),",
        "... ",
        "            ui.input_action_button(\"predict\", \"Predict\")]",
        "... ",
        "        ),",
        "... ",
        "        ui.panel_main(",
        "... ",
        "            ui.h2(\"Penguin Parameters\"),",
        "... ",
        "            ui.output_text_verbatim(\"vals_out\"),",
        "... ",
        "            ui.h2(\"Predicted Penguin Mass (g)\"), ",
        "... ",
        "            ui.output_text(\"pred_out\")",
        "... ",
        "        )",
        "... ",
        "    )   ",
        "... ",
        ")",
        ">>> ",
        ">>> ",
        "def server(input, output, session):",
        "... ",
        "    @reactive.Calc",
        "... ",
        "    def vals():",
        "... ",
        "        d = {",
        "... ",
        "            \"bill_length_mm\" : input.bill_length(),",
        "... ",
        "            \"sex_Male\" : input.sex() == \"Male\",",
        "... ",
        "            \"species_Gentoo\" : input.species() == \"Gentoo\", ",
        "... ",
        "            \"species_Chinstrap\" : input.species() == \"Chinstrap\"",
        "... ",
        "        ",
        "... ",
        "        }",
        "... ",
        "        return d",
        "... ",
        "    ",
        "... ",
        "    @reactive.Calc",
        "... ",
        "    @reactive.event(input.predict)",
        "... ",
        "    def pred():",
        "... ",
        "        r = requests.post(api_url, json = vals())",
        "... ",
        "        return r.json().get('predict')[0]",
        "... ",
        "        ",
        "... ",
        "    @output",
        "... ",
        "    @render.text",
        "... ",
        "    def vals_out():",
        "... ",
        "        return f\"{vals()}\"",
        "... ",
        "        ",
        "... ",
        "    @output",
        "... ",
        "    @render.text",
        "... ",
        "    def pred_out():",
        "... ",
        "        return f\"{round(pred())}\"",
        "... ",
        "        ",
        "... ",
        "app = App(app_ui, server)",
        ">>> ",
        ">>> ",
        ">>> ",
        ">>> ",
        ">>> ",
        "if __name__ == '__main__':",
        "... ",
        "    app.run()",
        "... ",
        "    ",
        "... ",
        "python pyapp.py",
        "INFO:     Started server process [20464]\r\nINFO:     Waiting for application startup.\r\nINFO:     Application startup complete.\r\nINFO:     Uvicorn running on http://127.0.0.1:8000 (Press CTRL+C to quit)\r\n",
        "INFO:     127.0.0.1:58876 - \"GET / HTTP/1.1\" 200 OK\r\nINFO:     127.0.0.1:58876 - \"GET /lib/requirejs-2.3.6/require.min.js HTTP/1.1\" 200 OK\r\nINFO:     127.0.0.1:58877 - \"GET /lib/jquery-3.6.0/jquery-3.6.0.min.js HTTP/1.1\" 200 OK\r\nINFO:     127.0.0.1:58878 - \"GET /lib/shiny-0.0.1/shiny.min.css HTTP/1.1\" 200 OK\r\nINFO:     127.0.0.1:58879 - \"GET /lib/bootstrap-5.3.1/bootstrap.min.css HTTP/1.1\" 200 OK\r\nINFO:     127.0.0.1:58880 - \"GET /lib/htmltools-fill-0.5.8.9000/fill.css HTTP/1.1\" 200 OK\r\nINFO:     127.0.0.1:",
        "58881 - \"GET /lib/preset-shiny-ionrangeslider-1.8.1.9000/css/ion.rangeSlider.css HTTP/1.1\" 200 OK\r\nINFO:     127.0.0.1:58878 - \"GET /lib/bslib-components-0.7.0.9000/components.css HTTP/1.1\" 200 OK\r\nINFO:     127.0.0.1:58880 - \"GET /lib/shiny-0.0.1/shiny.js HTTP/1.1\" 200 OK\r\nINFO:     127.0.0.1:58881 - \"GET /lib/bootstrap-5.3.1/bootstrap.bundle.min.js HTTP/1.1\" 200 OK\r\nINFO:     127.0.0.1:58878 - \"GET /lib/ionrangeslider-2.3.1/js/ion.rangeSlider.min.js HTTP/1.1\" 200 OK\r\nINFO:     127.0.0.1:58879 - \"GET /lib/",
        "strftime-0.9.2/strftime-min.js HTTP/1.1\" 200 OK\r\nINFO:     127.0.0.1:58879 - \"GET /lib/bslib-components-0.7.0.9000/components.min.js HTTP/1.1\" 200 OK\r\nINFO:     127.0.0.1:58876 - \"GET /lib/bslib-components-0.7.0.9000/web-components.min.js HTTP/1.1\" 200 OK\r\nINFO:     127.0.0.1:58880 - \"GET /lib/bootstrap-5.3.1/font.css HTTP/1.1\" 200 OK\r\nINFO:     127.0.0.1:58880 - \"GET /lib/bootstrap-5.3.1/fonts/memvYaGs126MiZpBA-UvWbX2vVnXBbObj2OVTS-muw.woff2 HTTP/1.1\" 200 OK\r\nINFO:     127.0.0.1:58876 - \"GET /lib/bootstrap",
        "-5.3.1/fonts/HI_SiYsKILxRpg3hIP6sJ7fM7PqlPevW.woff2 HTTP/1.1\" 200 OK\r\n",
        "INFO:     ('127.0.0.1', 58884) - \"WebSocket /websocket/\" [accepted]\r\nINFO:     connection open\r\n",
        "INFO:     127.0.0.1:58876 - \"GET /lib/bootstrap-5.3.1/fonts/memtYaGs126MiZpBA-UFUIcVXSCEkx2cmqvXlWqWuU6F.woff2 HTTP/1.1\" 200 OK\r\n",
        "Traceback (most recent call last):\r\n  File \"C:\\Users\\C25WES~1.PEE\\AppData\\Local\\Programs\\Python\\PYTHON~2\\Lib\\site-packages\\urllib3\\connection.py\", line 198, in _new_conn\r\n    sock = connection.create_connection(\r\n           ^^^^^^^^^^^^^^^^^^^^^^^^^^^^^\r\n  File \"C:\\Users\\C25WES~1.PEE\\AppData\\Local\\Programs\\Python\\PYTHON~2\\Lib\\site-packages\\urllib3\\util\\connection.py\", line 85, in create_connection\r\n    raise err\r\n  File \"C:\\Users\\C25WES~1.PEE\\AppData\\Local\\Programs\\Python\\PYTHON~2\\Lib\\site-packages\\urllib3\\",
        "util\\connection.py\", line 73, in create_connection\r\n    sock.connect(sa)\r\nConnectionRefusedError: [WinError 10061] No connection could be made because the target machine actively refused it\r\n\r\nThe above exception was the direct cause of the following exception:\r\n\r\nTraceback (most recent call last):\r\n  File \"C:\\Users\\C25WES~1.PEE\\AppData\\Local\\Programs\\Python\\PYTHON~2\\Lib\\site-packages\\urllib3\\connectionpool.py\", line 793, in urlopen\r\n    response = self._make_request(\r\n               ^^^^^^^^^^^^^^^^^^^\r\n  ",
        "File \"C:\\Users\\C25WES~1.PEE\\AppData\\Local\\Programs\\Python\\PYTHON~2\\Lib\\site-packages\\urllib3\\connectionpool.py\", line 496, in _make_request\r\n    conn.request(\r\n  File \"C:\\Users\\C25WES~1.PEE\\AppData\\Local\\Programs\\Python\\PYTHON~2\\Lib\\site-packages\\urllib3\\connection.py\", line 400, in request\r\n    self.endheaders()\r\n  File \"C:\\Users\\C25WES~1.PEE\\AppData\\Local\\Programs\\Python\\PYTHON~2\\Lib\\http\\client.py\", line 1331, in endheaders\r\n    self._send_output(message_body, encode_chunked=encode_chunked)\r\n  File \"C:\\U",
        "sers\\C25WES~1.PEE\\AppData\\Local\\Programs\\Python\\PYTHON~2\\Lib\\http\\client.py\", line 1091, in _send_output\r\n    self.send(msg)\r\n  File \"C:\\Users\\C25WES~1.PEE\\AppData\\Local\\Programs\\Python\\PYTHON~2\\Lib\\http\\client.py\", line 1035, in send\r\n    self.connect()\r\n  File \"C:\\Users\\C25WES~1.PEE\\AppData\\Local\\Programs\\Python\\PYTHON~2\\Lib\\site-packages\\urllib3\\connection.py\", line 238, in connect\r\n    self.sock = self._new_conn()\r\n                ^^^^^^^^^^^^^^^^\r\n  File \"C:\\Users\\C25WES~1.PEE\\AppData\\Local\\Programs\\Py",
        "thon\\PYTHON~2\\Lib\\site-packages\\urllib3\\connection.py\", line 213, in _new_conn\r\n    raise NewConnectionError(\r\nurllib3.exceptions.NewConnectionError: <urllib3.connection.HTTPConnection object at 0x0000017BC2313560>: Failed to establish a new connection: [WinError 10061] No connection could be made because the target machine actively refused it\r\n\r\nThe above exception was the direct cause of the following exception:\r\n\r\nTraceback (most recent call last):\r\n  File \"C:\\Users\\C25WES~1.PEE\\AppData\\Local\\Programs\\Py",
        "thon\\PYTHON~2\\Lib\\site-packages\\requests\\adapters.py\", line 486, in send\r\n    resp = conn.urlopen(\r\n           ^^^^^^^^^^^^^\r\n  File \"C:\\Users\\C25WES~1.PEE\\AppData\\Local\\Programs\\Python\\PYTHON~2\\Lib\\site-packages\\urllib3\\connectionpool.py\", line 847, in urlopen\r\n    retries = retries.increment(\r\n              ^^^^^^^^^^^^^^^^^^\r\n  File \"C:\\Users\\C25WES~1.PEE\\AppData\\Local\\Programs\\Python\\PYTHON~2\\Lib\\site-packages\\urllib3\\util\\retry.py\", line 515, in increment\r\n    raise MaxRetryError(_pool, url, reason) fr",
        "om reason  # type: ignore[arg-type]\r\n    ^^^^^^^^^^^^^^^^^^^^^^^^^^^^^^^^^^^^^^^^^^^^^^^^^^^\r\nurllib3.exceptions.MaxRetryError: HTTPConnectionPool(host='127.0.0.1', port=8080): Max retries exceeded with url: /predict (Caused by NewConnectionError('<urllib3.connection.HTTPConnection object at 0x0000017BC2313560>: Failed to establish a new connection: [WinError 10061] No connection could be made because the target machine actively refused it'))\r\n\r\nDuring handling of the above exception, another exception occu",
        "rred:\r\n\r\nTraceback (most recent call last):\r\n  File \"C:\\Users\\C25WES~1.PEE\\AppData\\Local\\Programs\\Python\\PYTHON~2\\Lib\\site-packages\\shiny\\session\\_session.py\", line 1220, in output_obs\r\n    value = await renderer.render()\r\n            ^^^^^^^^^^^^^^^^^^^^^^^\r\n  File \"C:\\Users\\C25WES~1.PEE\\AppData\\Local\\Programs\\Python\\PYTHON~2\\Lib\\site-packages\\shiny\\render\\renderer\\_renderer.py\", line 255, in render\r\n    value = await self.fn()\r\n            ^^^^^^^^^^^^^^^\r\n  File \"C:\\Users\\C25WES~1.PEE\\AppData\\Local\\Progr",
        "ams\\Python\\PYTHON~2\\Lib\\site-packages\\shiny\\render\\renderer\\_renderer.py\", line 349, in __call__\r\n    return await self._fn()\r\n           ^^^^^^^^^^^^^^^^\r\n  File \"C:\\Users\\C25WES~1.PEE\\AppData\\Local\\Programs\\Python\\PYTHON~2\\Lib\\site-packages\\shiny\\_utils.py\", line 263, in fn_async\r\n    return fn(*args, **kwargs)\r\n           ^^^^^^^^^^^^^^^^^^^\r\n  File \"<string>\", line 27, in pred_out\r\n  File \"C:\\Users\\C25WES~1.PEE\\AppData\\Local\\Programs\\Python\\PYTHON~2\\Lib\\site-packages\\shiny\\reactive\\_reactives.py\", line ",
        "283, in __call__\r\n    return _utils.run_coro_sync(self.get_value())\r\n           ^^^^^^^^^^^^^^^^^^^^^^^^^^^^^^^^^^^^^^\r\n  File \"C:\\Users\\C25WES~1.PEE\\AppData\\Local\\Programs\\Python\\PYTHON~2\\Lib\\site-packages\\shiny\\_utils.py\", line 378, in run_coro_sync\r\n    coro.send(None)\r\n  File \"C:\\Users\\C25WES~1.PEE\\AppData\\Local\\Programs\\Python\\PYTHON~2\\Lib\\site-packages\\shiny\\reactive\\_reactives.py\", line 293, in get_value\r\n    raise self._error[0]\r\n  File \"C:\\Users\\C25WES~1.PEE\\AppData\\Local\\Programs\\Python\\PYTHON~2\\L",
        "ib\\site-packages\\shiny\\reactive\\_reactives.py\", line 328, in _run_func\r\n    self._value.append(await self._fn())\r\n                       ^^^^^^^^^^^^^^^^\r\n  File \"C:\\Users\\C25WES~1.PEE\\AppData\\Local\\Programs\\Python\\PYTHON~2\\Lib\\site-packages\\shiny\\_utils.py\", line 263, in fn_async\r\n    return fn(*args, **kwargs)\r\n           ^^^^^^^^^^^^^^^^^^^\r\n  File \"C:\\Users\\C25WES~1.PEE\\AppData\\Local\\Programs\\Python\\PYTHON~2\\Lib\\site-packages\\shiny\\reactive\\_reactives.py\", line 877, in new_user_fn\r\n    return user_fn()\r",
        "\n           ^^^^^^^^^\r\n  File \"<string>\", line 16, in pred\r\n  File \"C:\\Users\\C25WES~1.PEE\\AppData\\Local\\Programs\\Python\\PYTHON~2\\Lib\\site-packages\\requests\\api.py\", line 115, in post\r\n    return request(\"post\", url, data=data, json=json, **kwargs)\r\n           ^^^^^^^^^^^^^^^^^^^^^^^^^^^^^^^^^^^^^^^^^^^^^^^^^^^^\r\n  File \"C:\\Users\\C25WES~1.PEE\\AppData\\Local\\Programs\\Python\\PYTHON~2\\Lib\\site-packages\\requests\\api.py\", line 59, in request\r\n    return session.request(method=method, url=url, **kwargs)\r\n          ",
        " ^^^^^^^^^^^^^^^^^^^^^^^^^^^^^^^^^^^^^^^^^^^^^^^^^\r\n  File \"C:\\Users\\C25WES~1.PEE\\AppData\\Local\\Programs\\Python\\PYTHON~2\\Lib\\site-packages\\requests\\sessions.py\", line 589, in request\r\n    resp = self.send(prep, **send_kwargs)\r\n           ^^^^^^^^^^^^^^^^^^^^^^^^^^^^^^\r\n  File \"C:\\Users\\C25WES~1.PEE\\AppData\\Local\\Programs\\Python\\PYTHON~2\\Lib\\site-packages\\requests\\sessions.py\", line 703, in send\r\n    r = adapter.send(request, **kwargs)\r\n        ^^^^^^^^^^^^^^^^^^^^^^^^^^^^^^^\r\n  File \"C:\\Users\\C25WES~1.PEE\\A",
        "ppData\\Local\\Programs\\Python\\PYTHON~2\\Lib\\site-packages\\requests\\adapters.py\", line 519, in send\r\n    raise ConnectionError(e, request=request)\r\nrequests.exceptions.ConnectionError: HTTPConnectionPool(host='127.0.0.1', port=8080): Max retries exceeded with url: /predict (Caused by NewConnectionError('<urllib3.connection.HTTPConnection object at 0x0000017BC2313560>: Failed to establish a new connection: [WinError 10061] No connection could be made because the target machine actively refused it'))\r\nTraceback ",
        "(most recent call last):\r\n  File \"C:\\Users\\C25WES~1.PEE\\AppData\\Local\\Programs\\Python\\PYTHON~2\\Lib\\site-packages\\urllib3\\connection.py\", line 198, in _new_conn\r\n    sock = connection.create_connection(\r\n           ^^^^^^^^^^^^^^^^^^^^^^^^^^^^^\r\n  File \"C:\\Users\\C25WES~1.PEE\\AppData\\Local\\Programs\\Python\\PYTHON~2\\Lib\\site-packages\\urllib3\\util\\connection.py\", line 85, in create_connection\r\n    raise err\r\n  File \"C:\\Users\\C25WES~1.PEE\\AppData\\Local\\Programs\\Python\\PYTHON~2\\Lib\\site-packages\\urllib3\\util\\conne",
        "ction.py\", line 73, in create_connection\r\n    sock.connect(sa)\r\nConnectionRefusedError: [WinError 10061] No connection could be made because the target machine actively refused it\r\n\r\nThe above exception was the direct cause of the following exception:\r\n\r\nTraceback (most recent call last):\r\n  File \"C:\\Users\\C25WES~1.PEE\\AppData\\Local\\Programs\\Python\\PYTHON~2\\Lib\\site-packages\\urllib3\\connectionpool.py\", line 793, in urlopen\r\n    response = self._make_request(\r\n               ^^^^^^^^^^^^^^^^^^^\r\n  File \"C:\\U",
        "sers\\C25WES~1.PEE\\AppData\\Local\\Programs\\Python\\PYTHON~2\\Lib\\site-packages\\urllib3\\connectionpool.py\", line 496, in _make_request\r\n    conn.request(\r\n  File \"C:\\Users\\C25WES~1.PEE\\AppData\\Local\\Programs\\Python\\PYTHON~2\\Lib\\site-packages\\urllib3\\connection.py\", line 400, in request\r\n    self.endheaders()\r\n  File \"C:\\Users\\C25WES~1.PEE\\AppData\\Local\\Programs\\Python\\PYTHON~2\\Lib\\http\\client.py\", line 1331, in endheaders\r\n    self._send_output(message_body, encode_chunked=encode_chunked)\r\n  File \"C:\\Users\\C25WE",
        "S~1.PEE\\AppData\\Local\\Programs\\Python\\PYTHON~2\\Lib\\http\\client.py\", line 1091, in _send_output\r\n    self.send(msg)\r\n  File \"C:\\Users\\C25WES~1.PEE\\AppData\\Local\\Programs\\Python\\PYTHON~2\\Lib\\http\\client.py\", line 1035, in send\r\n    self.connect()\r\n  File \"C:\\Users\\C25WES~1.PEE\\AppData\\Local\\Programs\\Python\\PYTHON~2\\Lib\\site-packages\\urllib3\\connection.py\", line 238, in connect\r\n    self.sock = self._new_conn()\r\n                ^^^^^^^^^^^^^^^^\r\n  File \"C:\\Users\\C25WES~1.PEE\\AppData\\Local\\Programs\\Python\\PYTHO",
        "N~2\\Lib\\site-packages\\urllib3\\connection.py\", line 213, in _new_conn\r\n    raise NewConnectionError(\r\nurllib3.exceptions.NewConnectionError: <urllib3.connection.HTTPConnection object at 0x0000017BC45AFD10>: Failed to establish a new connection: [WinError 10061] No connection could be made because the target machine actively refused it\r\n\r\nThe above exception was the direct cause of the following exception:\r\n\r\nTraceback (most recent call last):\r\n  File \"C:\\Users\\C25WES~1.PEE\\AppData\\Local\\Programs\\Python\\PYTHO",
        "N~2\\Lib\\site-packages\\requests\\adapters.py\", line 486, in send\r\n    resp = conn.urlopen(\r\n           ^^^^^^^^^^^^^\r\n  File \"C:\\Users\\C25WES~1.PEE\\AppData\\Local\\Programs\\Python\\PYTHON~2\\Lib\\site-packages\\urllib3\\connectionpool.py\", line 847, in urlopen\r\n    retries = retries.increment(\r\n              ^^^^^^^^^^^^^^^^^^\r\n  File \"C:\\Users\\C25WES~1.PEE\\AppData\\Local\\Programs\\Python\\PYTHON~2\\Lib\\site-packages\\urllib3\\util\\retry.py\", line 515, in increment\r\n    raise MaxRetryError(_pool, url, reason) from reason ",
        " # type: ignore[arg-type]\r\n    ^^^^^^^^^^^^^^^^^^^^^^^^^^^^^^^^^^^^^^^^^^^^^^^^^^^\r\nurllib3.exceptions.MaxRetryError: HTTPConnectionPool(host='127.0.0.1', port=8080): Max retries exceeded with url: /predict (Caused by NewConnectionError('<urllib3.connection.HTTPConnection object at 0x0000017BC45AFD10>: Failed to establish a new connection: [WinError 10061] No connection could be made because the target machine actively refused it'))\r\n\r\nDuring handling of the above exception, another exception occurred:\r\n\r\nT",
        "raceback (most recent call last):\r\n  File \"C:\\Users\\C25WES~1.PEE\\AppData\\Local\\Programs\\Python\\PYTHON~2\\Lib\\site-packages\\shiny\\session\\_session.py\", line 1220, in output_obs\r\n    value = await renderer.render()\r\n            ^^^^^^^^^^^^^^^^^^^^^^^\r\n  File \"C:\\Users\\C25WES~1.PEE\\AppData\\Local\\Programs\\Python\\PYTHON~2\\Lib\\site-packages\\shiny\\render\\renderer\\_renderer.py\", line 255, in render\r\n    value = await self.fn()\r\n            ^^^^^^^^^^^^^^^\r\n  File \"C:\\Users\\C25WES~1.PEE\\AppData\\Local\\Programs\\Python",
        "\\PYTHON~2\\Lib\\site-packages\\shiny\\render\\renderer\\_renderer.py\", line 349, in __call__\r\n    return await self._fn()\r\n           ^^^^^^^^^^^^^^^^\r\n  File \"C:\\Users\\C25WES~1.PEE\\AppData\\Local\\Programs\\Python\\PYTHON~2\\Lib\\site-packages\\shiny\\_utils.py\", line 263, in fn_async\r\n    return fn(*args, **kwargs)\r\n           ^^^^^^^^^^^^^^^^^^^\r\n  File \"<string>\", line 27, in pred_out\r\n  File \"C:\\Users\\C25WES~1.PEE\\AppData\\Local\\Programs\\Python\\PYTHON~2\\Lib\\site-packages\\shiny\\reactive\\_reactives.py\", line 283, in __",
        "call__\r\n    return _utils.run_coro_sync(self.get_value())\r\n           ^^^^^^^^^^^^^^^^^^^^^^^^^^^^^^^^^^^^^^\r\n  File \"C:\\Users\\C25WES~1.PEE\\AppData\\Local\\Programs\\Python\\PYTHON~2\\Lib\\site-packages\\shiny\\_utils.py\", line 378, in run_coro_sync\r\n    coro.send(None)\r\n  File \"C:\\Users\\C25WES~1.PEE\\AppData\\Local\\Programs\\Python\\PYTHON~2\\Lib\\site-packages\\shiny\\reactive\\_reactives.py\", line 293, in get_value\r\n    raise self._error[0]\r\n  File \"C:\\Users\\C25WES~1.PEE\\AppData\\Local\\Programs\\Python\\PYTHON~2\\Lib\\site-pa",
        "ckages\\shiny\\reactive\\_reactives.py\", line 328, in _run_func\r\n    self._value.append(await self._fn())\r\n                       ^^^^^^^^^^^^^^^^\r\n  File \"C:\\Users\\C25WES~1.PEE\\AppData\\Local\\Programs\\Python\\PYTHON~2\\Lib\\site-packages\\shiny\\_utils.py\", line 263, in fn_async\r\n    return fn(*args, **kwargs)\r\n           ^^^^^^^^^^^^^^^^^^^\r\n  File \"C:\\Users\\C25WES~1.PEE\\AppData\\Local\\Programs\\Python\\PYTHON~2\\Lib\\site-packages\\shiny\\reactive\\_reactives.py\", line 877, in new_user_fn\r\n    return user_fn()\r\n         ",
        "  ^^^^^^^^^\r\n  File \"<string>\", line 16, in pred\r\n  File \"C:\\Users\\C25WES~1.PEE\\AppData\\Local\\Programs\\Python\\PYTHON~2\\Lib\\site-packages\\requests\\api.py\", line 115, in post\r\n    return request(\"post\", url, data=data, json=json, **kwargs)\r\n           ^^^^^^^^^^^^^^^^^^^^^^^^^^^^^^^^^^^^^^^^^^^^^^^^^^^^\r\n  File \"C:\\Users\\C25WES~1.PEE\\AppData\\Local\\Programs\\Python\\PYTHON~2\\Lib\\site-packages\\requests\\api.py\", line 59, in request\r\n    return session.request(method=method, url=url, **kwargs)\r\n           ^^^^^^^^^",
        "^^^^^^^^^^^^^^^^^^^^^^^^^^^^^^^^^^^^^^^^\r\n  File \"C:\\Users\\C25WES~1.PEE\\AppData\\Local\\Programs\\Python\\PYTHON~2\\Lib\\site-packages\\requests\\sessions.py\", line 589, in request\r\n    resp = self.send(prep, **send_kwargs)\r\n           ^^^^^^^^^^^^^^^^^^^^^^^^^^^^^^\r\n  File \"C:\\Users\\C25WES~1.PEE\\AppData\\Local\\Programs\\Python\\PYTHON~2\\Lib\\site-packages\\requests\\sessions.py\", line 703, in send\r\n    r = adapter.send(request, **kwargs)\r\n        ^^^^^^^^^^^^^^^^^^^^^^^^^^^^^^^\r\n  File \"C:\\Users\\C25WES~1.PEE\\AppData\\Loc",
        "al\\Programs\\Python\\PYTHON~2\\Lib\\site-packages\\requests\\adapters.py\", line 519, in send\r\n    raise ConnectionError(e, request=request)\r\nrequests.exceptions.ConnectionError: HTTPConnectionPool(host='127.0.0.1', port=8080): Max retries exceeded with url: /predict (Caused by NewConnectionError('<urllib3.connection.HTTPConnection object at 0x0000017BC45AFD10>: Failed to establish a new connection: [WinError 10061] No connection could be made because the target machine actively refused it'))\r\nTraceback (most rece",
        "nt call last):\r\n  File \"C:\\Users\\C25WES~1.PEE\\AppData\\Local\\Programs\\Python\\PYTHON~2\\Lib\\site-packages\\urllib3\\connection.py\", line 198, in _new_conn\r\n    sock = connection.create_connection(\r\n           ^^^^^^^^^^^^^^^^^^^^^^^^^^^^^\r\n  File \"C:\\Users\\C25WES~1.PEE\\AppData\\Local\\Programs\\Python\\PYTHON~2\\Lib\\site-packages\\urllib3\\util\\connection.py\", line 85, in create_connection\r\n    raise err\r\n  File \"C:\\Users\\C25WES~1.PEE\\AppData\\Local\\Programs\\Python\\PYTHON~2\\Lib\\site-packages\\urllib3\\util\\connection.py\",",
        " line 73, in create_connection\r\n    sock.connect(sa)\r\nConnectionRefusedError: [WinError 10061] No connection could be made because the target machine actively refused it\r\n\r\nThe above exception was the direct cause of the following exception:\r\n\r\nTraceback (most recent call last):\r\n  File \"C:\\Users\\C25WES~1.PEE\\AppData\\Local\\Programs\\Python\\PYTHON~2\\Lib\\site-packages\\urllib3\\connectionpool.py\", line 793, in urlopen\r\n    response = self._make_request(\r\n               ^^^^^^^^^^^^^^^^^^^\r\n  File \"C:\\Users\\C25WE",
        "S~1.PEE\\AppData\\Local\\Programs\\Python\\PYTHON~2\\Lib\\site-packages\\urllib3\\connectionpool.py\", line 496, in _make_request\r\n    conn.request(\r\n  File \"C:\\Users\\C25WES~1.PEE\\AppData\\Local\\Programs\\Python\\PYTHON~2\\Lib\\site-packages\\urllib3\\connection.py\", line 400, in request\r\n    self.endheaders()\r\n  File \"C:\\Users\\C25WES~1.PEE\\AppData\\Local\\Programs\\Python\\PYTHON~2\\Lib\\http\\client.py\", line 1331, in endheaders\r\n    self._send_output(message_body, encode_chunked=encode_chunked)\r\n  File \"C:\\Users\\C25WES~1.PEE\\Ap",
        "pData\\Local\\Programs\\Python\\PYTHON~2\\Lib\\http\\client.py\", line 1091, in _send_output\r\n    self.send(msg)\r\n  File \"C:\\Users\\C25WES~1.PEE\\AppData\\Local\\Programs\\Python\\PYTHON~2\\Lib\\http\\client.py\", line 1035, in send\r\n    self.connect()\r\n  File \"C:\\Users\\C25WES~1.PEE\\AppData\\Local\\Programs\\Python\\PYTHON~2\\Lib\\site-packages\\urllib3\\connection.py\", line 238, in connect\r\n    self.sock = self._new_conn()\r\n                ^^^^^^^^^^^^^^^^\r\n  File \"C:\\Users\\C25WES~1.PEE\\AppData\\Local\\Programs\\Python\\PYTHON~2\\Lib\\si",
        "te-packages\\urllib3\\connection.py\", line 213, in _new_conn\r\n    raise NewConnectionError(\r\nurllib3.exceptions.NewConnectionError: <urllib3.connection.HTTPConnection object at 0x0000017BC47CCF80>: Failed to establish a new connection: [WinError 10061] No connection could be made because the target machine actively refused it\r\n\r\nThe above exception was the direct cause of the following exception:\r\n\r\nTraceback (most recent call last):\r\n  File \"C:\\Users\\C25WES~1.PEE\\AppData\\Local\\Programs\\Python\\PYTHON~2\\Lib\\si",
        "te-packages\\requests\\adapters.py\", line 486, in send\r\n    resp = conn.urlopen(\r\n           ^^^^^^^^^^^^^\r\n  File \"C:\\Users\\C25WES~1.PEE\\AppData\\Local\\Programs\\Python\\PYTHON~2\\Lib\\site-packages\\urllib3\\connectionpool.py\", line 847, in urlopen\r\n    retries = retries.increment(\r\n              ^^^^^^^^^^^^^^^^^^\r\n  File \"C:\\Users\\C25WES~1.PEE\\AppData\\Local\\Programs\\Python\\PYTHON~2\\Lib\\site-packages\\urllib3\\util\\retry.py\", line 515, in increment\r\n    raise MaxRetryError(_pool, url, reason) from reason  # type: i",
        "gnore[arg-type]\r\n    ^^^^^^^^^^^^^^^^^^^^^^^^^^^^^^^^^^^^^^^^^^^^^^^^^^^\r\nurllib3.exceptions.MaxRetryError: HTTPConnectionPool(host='127.0.0.1', port=8080): Max retries exceeded with url: /predict (Caused by NewConnectionError('<urllib3.connection.HTTPConnection object at 0x0000017BC47CCF80>: Failed to establish a new connection: [WinError 10061] No connection could be made because the target machine actively refused it'))\r\n\r\nDuring handling of the above exception, another exception occurred:\r\n\r\nTraceback (",
        "most recent call last):\r\n  File \"C:\\Users\\C25WES~1.PEE\\AppData\\Local\\Programs\\Python\\PYTHON~2\\Lib\\site-packages\\shiny\\session\\_session.py\", line 1220, in output_obs\r\n    value = await renderer.render()\r\n            ^^^^^^^^^^^^^^^^^^^^^^^\r\n  File \"C:\\Users\\C25WES~1.PEE\\AppData\\Local\\Programs\\Python\\PYTHON~2\\Lib\\site-packages\\shiny\\render\\renderer\\_renderer.py\", line 255, in render\r\n    value = await self.fn()\r\n            ^^^^^^^^^^^^^^^\r\n  File \"C:\\Users\\C25WES~1.PEE\\AppData\\Local\\Programs\\Python\\PYTHON~2\\",
        "Lib\\site-packages\\shiny\\render\\renderer\\_renderer.py\", line 349, in __call__\r\n    return await self._fn()\r\n           ^^^^^^^^^^^^^^^^\r\n  File \"C:\\Users\\C25WES~1.PEE\\AppData\\Local\\Programs\\Python\\PYTHON~2\\Lib\\site-packages\\shiny\\_utils.py\", line 263, in fn_async\r\n    return fn(*args, **kwargs)\r\n           ^^^^^^^^^^^^^^^^^^^\r\n  File \"<string>\", line 27, in pred_out\r\n  File \"C:\\Users\\C25WES~1.PEE\\AppData\\Local\\Programs\\Python\\PYTHON~2\\Lib\\site-packages\\shiny\\reactive\\_reactives.py\", line 283, in __call__\r\n  ",
        "  return _utils.run_coro_sync(self.get_value())\r\n           ^^^^^^^^^^^^^^^^^^^^^^^^^^^^^^^^^^^^^^\r\n  File \"C:\\Users\\C25WES~1.PEE\\AppData\\Local\\Programs\\Python\\PYTHON~2\\Lib\\site-packages\\shiny\\_utils.py\", line 378, in run_coro_sync\r\n    coro.send(None)\r\n  File \"C:\\Users\\C25WES~1.PEE\\AppData\\Local\\Programs\\Python\\PYTHON~2\\Lib\\site-packages\\shiny\\reactive\\_reactives.py\", line 293, in get_value\r\n    raise self._error[0]\r\n  File \"C:\\Users\\C25WES~1.PEE\\AppData\\Local\\Programs\\Python\\PYTHON~2\\Lib\\site-packages\\shi",
        "ny\\reactive\\_reactives.py\", line 328, in _run_func\r\n    self._value.append(await self._fn())\r\n                       ^^^^^^^^^^^^^^^^\r\n  File \"C:\\Users\\C25WES~1.PEE\\AppData\\Local\\Programs\\Python\\PYTHON~2\\Lib\\site-packages\\shiny\\_utils.py\", line 263, in fn_async\r\n    return fn(*args, **kwargs)\r\n           ^^^^^^^^^^^^^^^^^^^\r\n  File \"C:\\Users\\C25WES~1.PEE\\AppData\\Local\\Programs\\Python\\PYTHON~2\\Lib\\site-packages\\shiny\\reactive\\_reactives.py\", line 877, in new_user_fn\r\n    return user_fn()\r\n           ^^^^^^^^",
        "^\r\n  File \"<string>\", line 16, in pred\r\n  File \"C:\\Users\\C25WES~1.PEE\\AppData\\Local\\Programs\\Python\\PYTHON~2\\Lib\\site-packages\\requests\\api.py\", line 115, in post\r\n    return request(\"post\", url, data=data, json=json, **kwargs)\r\n           ^^^^^^^^^^^^^^^^^^^^^^^^^^^^^^^^^^^^^^^^^^^^^^^^^^^^\r\n  File \"C:\\Users\\C25WES~1.PEE\\AppData\\Local\\Programs\\Python\\PYTHON~2\\Lib\\site-packages\\requests\\api.py\", line 59, in request\r\n    return session.request(method=method, url=url, **kwargs)\r\n           ^^^^^^^^^^^^^^^^^^^",
        "^^^^^^^^^^^^^^^^^^^^^^^^^^^^^^\r\n  File \"C:\\Users\\C25WES~1.PEE\\AppData\\Local\\Programs\\Python\\PYTHON~2\\Lib\\site-packages\\requests\\sessions.py\", line 589, in request\r\n    resp = self.send(prep, **send_kwargs)\r\n           ^^^^^^^^^^^^^^^^^^^^^^^^^^^^^^\r\n  File \"C:\\Users\\C25WES~1.PEE\\AppData\\Local\\Programs\\Python\\PYTHON~2\\Lib\\site-packages\\requests\\sessions.py\", line 703, in send\r\n    r = adapter.send(request, **kwargs)\r\n        ^^^^^^^^^^^^^^^^^^^^^^^^^^^^^^^\r\n  File \"C:\\Users\\C25WES~1.PEE\\AppData\\Local\\Program",
        "s\\Python\\PYTHON~2\\Lib\\site-packages\\requests\\adapters.py\", line 519, in send\r\n    raise ConnectionError(e, request=request)\r\nrequests.exceptions.ConnectionError: HTTPConnectionPool(host='127.0.0.1', port=8080): Max retries exceeded with url: /predict (Caused by NewConnectionError('<urllib3.connection.HTTPConnection object at 0x0000017BC47CCF80>: Failed to establish a new connection: [WinError 10061] No connection could be made because the target machine actively refused it'))\r\n",
        "\nRestarting R session...\n\n",
        "- Project '~/QUARTOPROJECT' loaded. [renv 1.0.7]\n- The project is out-of-sync -- use `renv::status()` for details.\n",
        "> ",
        "reticulate::repl_python()",
        "Python 3.12.3 (C:/Users/C25Weston.Peene/AppData/Local/Programs/Python/Python312/python.exe)\nReticulate 1.36.0 REPL -- A Python interpreter in R.\nEnter 'exit' or 'quit' to exit the REPL and return to R.\n",
        ">>> ",
        "from shiny import App, render, ui, reactive",
        ">>> ",
        "import requests",
        ">>> ",
        "import logging",
        ">>> ",
        ">>> ",
        "api_url = 'http://127.0.0.1:8080/predict'",
        ">>> ",
        "logging.basicConfig(",
        "... ",
        "    format='%(asctime)s - %(message)s',",
        "... ",
        "    level=logging.INFO",
        "... ",
        ")",
        ">>> ",
        ">>> ",
        "app_ui = ui.page_fluid(",
        "... ",
        "    ui.panel_title(\"Penguin Mass Predictor\"), ",
        "... ",
        "    ui.layout_sidebar(",
        "... ",
        "        ui.panel_sidebar(",
        "... ",
        "            [ui.input_slider(\"bill_length\", \"Bill Length (mm)\", 30, 60, 45, step = 0.1),",
        "... ",
        "            ui.input_select(\"sex\", \"Sex\", [\"Male\", \"Female\"]),",
        "... ",
        "            ui.input_select(\"species\", \"Species\", [\"Adelie\", \"Chinstrap\", \"Gentoo\"]),",
        "... ",
        "            ui.input_action_button(\"predict\", \"Predict\")]",
        "... ",
        "        ),",
        "... ",
        "        ui.panel_main(",
        "... ",
        "            ui.h2(\"Penguin Parameters\"),",
        "... ",
        "            ui.output_text_verbatim(\"vals_out\"),",
        "... ",
        "            ui.h2(\"Predicted Penguin Mass (g)\"), ",
        "... ",
        "            ui.output_text(\"pred_out\")",
        "... ",
        "        )",
        "... ",
        "    )   ",
        "... ",
        ")",
        ">>> ",
        ">>> ",
        "def server(input, output, session):",
        "... ",
        "    logging.info(\"App start\")",
        "... ",
        "    ",
        "... ",
        "    @reactive.Calc",
        "... ",
        "    def vals():",
        "... ",
        "        d = {",
        "... ",
        "            \"bill_length_mm\" : input.bill_length(),",
        "... ",
        "            \"sex_Male\" : input.sex() == \"Male\",",
        "... ",
        "            \"species_Gentoo\" : input.species() == \"Gentoo\", ",
        "... ",
        "            \"species_Chinstrap\" : input.species() == \"Chinstrap\"",
        "... ",
        "        ",
        "... ",
        "        }",
        "... ",
        "        return d",
        "... ",
        "    ",
        "... ",
        "    @reactive.Calc",
        "... ",
        "    @reactive.event(input.predict)",
        "... ",
        "    def pred():",
        "... ",
        "        logging.info(\"Request Made\")",
        "... ",
        "        r = requests.post(api_url, json = vals())",
        "... ",
        "        logging.info(\"Request Returned\")",
        "... ",
        "        ",
        "... ",
        "        if r.status_code != 200:",
        "... ",
        "            logging.error(\"HTTP error returned\")",
        "... ",
        "            ",
        "... ",
        "        return r.json().get('predict')[0]",
        "... ",
        "        ",
        "... ",
        "    @output",
        "... ",
        "    @render.text",
        "... ",
        "    def vals_out():",
        "... ",
        "        return f\"{vals()}\"",
        "... ",
        "        ",
        "... ",
        "    @output",
        "... ",
        "    @render.text",
        "... ",
        "    def pred_out():",
        "... ",
        "        return f\"{round(pred())}\"",
        "... ",
        "        ",
        "... ",
        "app = App(app_ui, server)",
        ">>> ",
        ">>> ",
        "python pyapp.py",
        "  File \"<string>\", line 1\n    python pyapp.py\n           ^^^^^\nSyntaxError: invalid syntax\n",
        ">>> ",
        "from flask import Flask",
        ">>> ",
        ">>> ",
        "app = Flask(__name__)",
        ">>> ",
        ">>> ",
        "@app.route('/')",
        "... ",
        "if __name__ == '__main__':",
        "  File \"<string>\", line 1\n    @app.route('/')\nSyntaxError: invalid syntax\n",
        "... ",
        "    app.run()",
        "... ",
        "    ",
        "... ",
        "python pyapp.py",
        " * Serving Flask app '__main__'\r\n * Debug mode: off\r\n",
        "2024-04-18 10:48:57,028 - \u001B[31m\u001B[1mWARNING: This is a development server. Do not use it in a production deployment. Use a production WSGI server instead.\u001B[0m\r\n * Running on http://127.0.0.1:5000\r\n2024-04-18 10:48:57,028 - \u001B[33mPress CTRL+C to quit\u001B[0m\r\n2024-04-18 10:49:07,348 - 127.0.0.1 - - [18/Apr/2024 10:49:07] \"\u001B[33mGET / HTTP/1.1\u001B[0m\" 404 -\r\n",
        "\nRestarting R session...\n\n"
    ]
}